<mujoco model='ADROIT-door(v1.5)'>
    
    <!-- ======= WORLD ======= -->
    <worldbody>
        <light directional='false' diffuse='.7 .7 .7' specular='0.03 0.03 0.03' pos='-1 -1.0 4.0' dir='1 1.0 -4'/>
        <geom name='ground' size="1.5 1.5 0.25" pos="0 0 -1" type="plane" contype="1" conaffinity="0" material="groundplane" />
        <camera name="fixed" pos="0 -0.7 0.7" quat="0.92388 0.382683 0 0" />
        <!-- Camera for the VIL paper -->
        <camera name="vil_camera" pos="0 -1.2 1.2" quat="0.92388 0.382683 0 0" />
 
        <!-- ======= TABLE ======= -->
        <body name="table">
            <!-- <geom size="0.5 0.5 0.025" type="plane" material="table2d" /> --> <!-- Plane has better contacts -->
            <geom size="0.45 0.45 0.025" pos="0 0 -0.025" type="box" material="tablecube" />
            <geom size="0.04 0.5" pos="0.4 0.4 -0.501" quat="0 1 0 0" type="cylinder" contype="0" conaffinity="0" />
            <geom size="0.04 0.5" pos="-0.4 0.4 -0.501" quat="0 1 0 0" type="cylinder" contype="0" conaffinity="0" />
            <geom size="0.04 0.5" pos="0.4 -0.4 -0.501" quat="0 1 0 0" type="cylinder" contype="0" conaffinity="0" />
            <geom size="0.04 0.5" pos="-0.4 -0.4 -0.501" quat="0 1 0 0" type="cylinder" contype="0" conaffinity="0" />
        </body>
        
        <!-- ======= MOCAP ======= -->
        <body name="vive_tracker" pos="0 -0.35 0.25" mocap="true">
            <inertial pos="0 0 0" mass="0.064" diaginertia="1.70667e-05 1.70667e-05 1.70667e-05" />
            <geom size="0.03 0.01" type="cylinder" contype="0" conaffinity="0" group="3" rgba="0.3 0.3 0.3 0.3" />
        </body>

        <!-- ======= HAND ======= -->
        <body name="robotwrist_rolllink" pos="0.0 -0.3 0.35" euler="1.57 -1.57 0">
            <camera fovy="60" mode="fixed" name="robot_camera1" pos="-0.05 -0.05 0.05" euler="1.57 1.57 0"/>
            <camera fovy="60" mode="fixed" name="robot_camera2" pos="-0.05 0.05 0.05" euler="1.57 1.57 0"/>
            <inertial pos="-0.0641638075944594 2.70691865020822e-05 0.00526385736219506" quat="0.999999 0.000484212 -0.00134643 -0.000743041" mass="0.657109755986862" fullinertia="0.0057866591250737 0.00530223654324281 0.00342399181200673 3.71515699629511e-07 -6.32890111626103e-05 8.9999884666805e-07" />
            <geom name="link" type="mesh" rgba="0.792157 0.819608 0.933333 1" mesh="wrist_roll_link" contype="16" conaffinity="7" euler="0 1.57 0" />
            <joint name="wrist_x_slide_joint" type="slide" pos="-0.0641638075944594 2.70691865020822e-05 0.00526385736219506" axis="1 0 0" limited="true" range="-0.4 0.2" />
            <joint name="wrist_y_slide_joint" type="slide" pos="-0.0641638075944594 2.70691865020822e-05 0.00526385736219506" axis="0 1 0" limited="true" range="-0.3 0.2" />
            <joint name="wrist_z_slide_joint" type="slide" pos="-0.0641638075944594 2.70691865020822e-05 0.00526385736219506" axis="0 0 1" limited="true" range="-0.3 0.3" />
            <joint name="wrist_z_hinge_joint" type="hinge" pos="-0.0641638075944594 2.70691865020822e-05 0.00526385736219506" axis="0 0 1" limited="true" range="-0.1 0.1" />
            <joint name="wrist_y_hinge_joint" type="hinge" pos="-0.0641638075944594 2.70691865020822e-05 0.00526385736219506" axis="0 1 0" limited="true" range="-0.1 0.1" />
            <joint name="wrist_x_hinge_joint" type="hinge" pos="-0.0641638075944594 2.70691865020822e-05 0.00526385736219506" axis="1 0 0" limited="true" range="0 3.13" />
            <body name="robotfinger_hook" pos="-0.0 -0.04 0" euler="0 0 0">
                <inertial pos="0 0 0" quat="1 0 0 0" mass="0.0001" diaginertia="3.916e-5 4.278e-5 4.8095e-6"/>
                <geom friction="1 1 1" type="mesh" mesh="hook_0" name="hookfinger_0" euler="0 0 0" condim="3"/>
                <!-- <geom friction="1 1 1" type="mesh" mesh="hook_3" name="hookfinger_3" euler="0 0 0" condim="3"/> -->
                <geom friction="1 1 1" type="mesh" mesh="hook_1" name="hookfinger_1" euler="0 0 0" condim="3"/>
                <body name="robotfinger_hook_target">
                    <geom friction="1 1 1" type="mesh" mesh="hook_2" name="hookfinger_2" euler="0 0 0" condim="3" rgba="1 1 1 1"/>
                    <site name="eef_grasp_pos" type="sphere" pos="-0.15 0.04 0.0" size="0.03"  rgba="0.0 0.0 1.0 1.0"/>
                </body>
            </body>
        </body>

        <!-- ======= DOOR ======= -->
        <body name="frame" pos="-0.107339 0.0435293 0.447376" user="1001 0 2002 -0.4 -0.1 0.252 0 0.3 0.45">
            <inertial pos="0.29 0 0" quat="0.5 0.5 0.5 0.5" mass="7.85398" diaginertia="0.923301 0.764585 0.168533" />
            <geom size="0.05 0.25" pos="0.6 0 0" type="cylinder" material="MatWood" rgba="1 0 0 1" />
            <geom size="0.05 0.25" pos="-0.02 0 0" type="cylinder" material="MatWood" rgba="1 0 0 1" />
            <site name="S_handle_target" pos="0.75 -0.5 -.18" size="0.025" group='3'/>
            <body name="door" pos="0.29 0 0">
                <inertial pos="0.0296816 -0.00152345 0" quat="0.701072 0 0 0.713091" mass="2.43455" diaginertia="0.0913751 0.0521615 0.043714" />
                <joint name="door_hinge" pos="0.31 0 0" axis="0 0 1" range="0 1.57" damping="1" frictionloss="0.3" />
                <geom size="0.2 0.05 0.25" type="box" friction="1 1 1" material="MatWood" />
                <geom size="0.05 0.25" pos="0.2 0 0" type="cylinder" material="MatWood" />
                <geom size="0.05 0.25" pos="-0.2 0 0" type="cylinder" material="MatWood" />
                <body name="latch" pos="-0.15 0 -0.025">
                    <inertial pos="-0.017762 0.0138544 0" quat="0.365653 0.605347 -0.36522 0.605365" mass="0.3" diaginertia="0.0483771 0.0410001 0.0111013" />
                    <joint name="latch" pos="0 0 0" axis="0 1 0" range="0 2.0" frictionloss="0.1" /> 
                    <!-- delete the range above -->
                    <geom size="0.05 0.15" quat="0.707388 0.706825 0 0" type="cylinder" material="MatFoil" />
                    <geom size="0.02 0.2" pos="0. -0.15 0" quat="0.707388 0 0.706825 0" type="capsule" material="MatFoil" />
                    <geom size="0.02 0.2" pos="0. -0.15 0" quat="1 0 0 0" type="capsule" material="MatFoil" />
                    <geom size="0.04 0.07" pos="-0.1 0.1 0" quat="0.707388 0 0.706825 0" type="capsule" material="MatFoil" />
                    <site name="S_handle" type="sphere" pos="0.15 -0.15 0" size="0.03"  rgba="0.0 1.0 0.0 1.0"/>
                    <site name="knob_hinge" type="sphere" pos="0 -0.15 0" size="0.05"  rgba="1.0 0.0 0.0 1.0"/>
                </body>
            </body>
        </body>
        
    </worldbody>
    
     <actuator>
        <motor ctrllimited="true" ctrlrange="-1.0 1.0" gear="2.0" joint="wrist_x_slide_joint" />
        <motor ctrllimited="true" ctrlrange="-1.0 1.0" gear="2.0" joint="wrist_y_slide_joint" />
        <motor ctrllimited="true" ctrlrange="-1.0 1.0" gear="2.0" joint="wrist_z_slide_joint" />
        <motor ctrllimited="true" ctrlrange="-1.0 1.0" gear="2.0" joint="wrist_z_hinge_joint" />
        <motor ctrllimited="true" ctrlrange="-1.0 1.0" gear="2.0" joint="wrist_y_hinge_joint" />
        <motor ctrllimited="true" ctrlrange="-1.0 1.0" gear="2.0" joint="wrist_x_hinge_joint" />        
	</actuator>
    <include file='DAPG_assets_hook.xml'/>

</mujoco>
